=== PHASE 7: AUTOMATED TESTING & COVERAGE ===

7.1 Running full test suite...
time="2025-10-19T01:41:50+05:30" level=warning msg="C:\\Users\\srina\\OneDrive\\Documents\\Downloads\\Stealth-Reecovery-20251010T154256Z-1-001\\Stealth-Reecovery\\docker-compose.yml: the attribute `version` is obsolete, it will be ignored, please remove it to avoid potential confusion"
/usr/local/lib/python3.11/site-packages/pytest_asyncio/plugin.py:207: PytestDeprecationWarning: The configuration option "asyncio_default_fixture_loop_scope" is unset.
The event loop scope for asynchronous fixtures will default to the fixture caching scope. Future versions of pytest-asyncio will default the loop scope for asynchronous fixtures to function scope. Set the default fixture loop scope explicitly in order to avoid unexpected behavior in the future. Valid fixture loop scopes are: "function", "class", "module", "package", "session"

  warnings.warn(PytestDeprecationWarning(_DEFAULT_FIXTURE_LOOP_SCOPE_UNSET))
============================= test session starts ==============================
platform linux -- Python 3.11.14, pytest-8.3.4, pluggy-1.6.0 -- /usr/local/bin/python
cachedir: .pytest_cache
rootdir: /app
plugins: anyio-4.11.0, asyncio-0.25.2
asyncio: mode=Mode.STRICT, asyncio_default_fixture_loop_scope=None
collecting ... collected 43 items

tests/test_auth.py::test_register_new_user PASSED                        [  2%]
tests/test_auth.py::test_register_duplicate_email PASSED                 [  4%]
tests/test_auth.py::test_register_duplicate_org_slug PASSED              [  6%]
tests/test_auth.py::test_login_success PASSED                            [  9%]
tests/test_auth.py::test_login_wrong_password PASSED                     [ 11%]
tests/test_auth.py::test_login_nonexistent_user PASSED                   [ 13%]
tests/test_auth.py::test_get_current_user PASSED                         [ 16%]
tests/test_auth.py::test_get_current_user_no_token PASSED                [ 18%]
tests/test_auth.py::test_get_current_user_invalid_token PASSED           [ 20%]
tests/test_auth.py::test_get_current_organization PASSED                 [ 23%]
tests/test_classifier.py::test_known_code_issuer_declined PASSED         [ 25%]
tests/test_classifier.py::test_message_auth_timeout PASSED               [ 27%]
tests/test_classifier.py::test_message_funds PASSED                      [ 30%]
tests/test_classifier.py::test_unknown_defaults PASSED                   [ 32%]
tests/test_payments_checkout.py::test_checkout_503_without_config PASSED [ 34%]
tests/test_payments_checkout.py::test_checkout_success_with_mock PASSED  [ 37%]
tests/test_payments_stripe.py::test_create_intent_when_not_configured_returns_503 PASSED [ 39%]
tests/test_payments_stripe.py::test_create_intent_success_with_mock PASSED [ 41%]
tests/test_recovery_links.py::test_valid_token_flow PASSED               [ 44%]
tests/test_recovery_links.py::test_expired_token PASSED                  [ 46%]
tests/test_recovery_links.py::test_used_token PASSED                     [ 48%]
tests/test_retry.py::test_calculate_next_retry PASSED                    [ 51%]
tests/test_retry.py::test_create_retry_policy PASSED                     [ 53%]
tests/test_retry.py::test_list_retry_policies PASSED                     [ 55%]
tests/test_retry.py::test_get_active_policy PASSED                       [ 58%]
tests/test_retry.py::test_deactivate_policy PASSED                       [ 60%]
tests/test_retry.py::test_get_retry_stats FAILED                         [ 62%]
tests/test_retry.py::test_notification_log_creation PASSED               [ 65%]
tests/test_retry.py::test_get_attempt_notifications PASSED               [ 67%]
tests/test_retry.py::test_trigger_immediate_retry PASSED                 [ 69%]
tests/test_stripe_integration.py::test_create_checkout_session_success ERROR [ 72%]
tests/test_stripe_integration.py::test_create_checkout_session_transaction_not_found ERROR [ 74%]
tests/test_stripe_integration.py::test_create_checkout_session_stripe_error ERROR [ 76%]
tests/test_stripe_integration.py::test_create_payment_link_success ERROR [ 79%]
tests/test_stripe_integration.py::test_get_session_status_success ERROR  [ 81%]
tests/test_stripe_integration.py::test_get_session_status_not_found ERROR [ 83%]
tests/test_stripe_integration.py::test_webhook_checkout_session_completed ERROR [ 86%]
tests/test_stripe_integration.py::test_webhook_payment_intent_succeeded ERROR [ 88%]
tests/test_stripe_integration.py::test_webhook_missing_signature ERROR   [ 90%]

==================================== ERRORS ====================================
____________ ERROR at setup of test_create_checkout_session_success ____________
file /app/tests/test_stripe_integration.py, line 119
  @patch('app.services.stripe_service.stripe.checkout.Session.create')
  def test_create_checkout_session_success(mock_stripe_create, client, auth_headers, test_transaction):
E       fixture 'client' not found
>       available fixtures: _session_event_loop, anyio_backend, anyio_backend_name, anyio_backend_options, auth_headers, cache, capfd, capfdbinary, caplog, capsys, capsysbinary, clean_db, db_session, doctest_namespace, event_loop, event_loop_policy, free_tcp_port, free_tcp_port_factory, free_udp_port, free_udp_port_factory, monkeypatch, pytestconfig, record_property, record_testsuite_property, record_xml_attribute, recwarn, test_org, test_transaction, test_user, tests/test_stripe_integration.py::<event_loop>, tmp_path, tmp_path_factory, tmpdir, tmpdir_factory, unused_tcp_port, unused_tcp_port_factory, unused_udp_port, unused_udp_port_factory
>       use 'pytest --fixtures [testpath]' for help on them.

/app/tests/test_stripe_integration.py:119
_____ ERROR at setup of test_create_checkout_session_transaction_not_found _____
file /app/tests/test_stripe_integration.py, line 158
  @patch('app.services.stripe_service.stripe.checkout.Session.create')
  def test_create_checkout_session_transaction_not_found(mock_stripe_create, client, auth_headers):
E       fixture 'client' not found
>       available fixtures: _session_event_loop, anyio_backend, anyio_backend_name, anyio_backend_options, auth_headers, cache, capfd, capfdbinary, caplog, capsys, capsysbinary, clean_db, db_session, doctest_namespace, event_loop, event_loop_policy, free_tcp_port, free_tcp_port_factory, free_udp_port, free_udp_port_factory, monkeypatch, pytestconfig, record_property, record_testsuite_property, record_xml_attribute, recwarn, test_org, test_transaction, test_user, tests/test_stripe_integration.py::<event_loop>, tmp_path, tmp_path_factory, tmpdir, tmpdir_factory, unused_tcp_port, unused_tcp_port_factory, unused_udp_port, unused_udp_port_factory
>       use 'pytest --fixtures [testpath]' for help on them.

/app/tests/test_stripe_integration.py:158
_________ ERROR at setup of test_create_checkout_session_stripe_error __________
file /app/tests/test_stripe_integration.py, line 176
  @patch('app.services.stripe_service.stripe.checkout.Session.create')
  def test_create_checkout_session_stripe_error(mock_stripe_create, client, auth_headers, test_transaction):
E       fixture 'client' not found
>       available fixtures: _session_event_loop, anyio_backend, anyio_backend_name, anyio_backend_options, auth_headers, cache, capfd, capfdbinary, caplog, capsys, capsysbinary, clean_db, db_session, doctest_namespace, event_loop, event_loop_policy, free_tcp_port, free_tcp_port_factory, free_udp_port, free_udp_port_factory, monkeypatch, pytestconfig, record_property, record_testsuite_property, record_xml_attribute, recwarn, test_org, test_transaction, test_user, tests/test_stripe_integration.py::<event_loop>, tmp_path, tmp_path_factory, tmpdir, tmpdir_factory, unused_tcp_port, unused_tcp_port_factory, unused_udp_port, unused_udp_port_factory
>       use 'pytest --fixtures [testpath]' for help on them.

/app/tests/test_stripe_integration.py:176
______________ ERROR at setup of test_create_payment_link_success ______________
file /app/tests/test_stripe_integration.py, line 203
  @patch('app.services.stripe_service.stripe.PaymentLink.create')
  @patch('app.services.stripe_service.stripe.Price.create')
  @patch('app.services.stripe_service.stripe.Product.create')
  def test_create_payment_link_success(mock_product_create, mock_price_create, mock_link_create,
E       fixture 'client' not found
>       available fixtures: _session_event_loop, anyio_backend, anyio_backend_name, anyio_backend_options, auth_headers, cache, capfd, capfdbinary, caplog, capsys, capsysbinary, clean_db, db_session, doctest_namespace, event_loop, event_loop_policy, free_tcp_port, free_tcp_port_factory, free_udp_port, free_udp_port_factory, monkeypatch, pytestconfig, record_property, record_testsuite_property, record_xml_attribute, recwarn, test_org, test_transaction, test_user, tests/test_stripe_integration.py::<event_loop>, tmp_path, tmp_path_factory, tmpdir, tmpdir_factory, unused_tcp_port, unused_tcp_port_factory, unused_udp_port, unused_udp_port_factory
>       use 'pytest --fixtures [testpath]' for help on them.

/app/tests/test_stripe_integration.py:203
______________ ERROR at setup of test_get_session_status_success _______________
file /app/tests/test_stripe_integration.py, line 252
  @patch('app.services.stripe_service.stripe.checkout.Session.retrieve')
  def test_get_session_status_success(mock_retrieve, client, auth_headers):
E       fixture 'client' not found
>       available fixtures: _session_event_loop, anyio_backend, anyio_backend_name, anyio_backend_options, auth_headers, cache, capfd, capfdbinary, caplog, capsys, capsysbinary, clean_db, db_session, doctest_namespace, event_loop, event_loop_policy, free_tcp_port, free_tcp_port_factory, free_udp_port, free_udp_port_factory, monkeypatch, pytestconfig, record_property, record_testsuite_property, record_xml_attribute, recwarn, test_org, test_transaction, test_user, tests/test_stripe_integration.py::<event_loop>, tmp_path, tmp_path_factory, tmpdir, tmpdir_factory, unused_tcp_port, unused_tcp_port_factory, unused_udp_port, unused_udp_port_factory
>       use 'pytest --fixtures [testpath]' for help on them.

/app/tests/test_stripe_integration.py:252
_____________ ERROR at setup of test_get_session_status_not_found ______________
file /app/tests/test_stripe_integration.py, line 282
  @patch('app.services.stripe_service.stripe.checkout.Session.retrieve')
  def test_get_session_status_not_found(mock_retrieve, client, auth_headers):
E       fixture 'client' not found
>       available fixtures: _session_event_loop, anyio_backend, anyio_backend_name, anyio_backend_options, auth_headers, cache, capfd, capfdbinary, caplog, capsys, capsysbinary, clean_db, db_session, doctest_namespace, event_loop, event_loop_policy, free_tcp_port, free_tcp_port_factory, free_udp_port, free_udp_port_factory, monkeypatch, pytestconfig, record_property, record_testsuite_property, record_xml_attribute, recwarn, test_org, test_transaction, test_user, tests/test_stripe_integration.py::<event_loop>, tmp_path, tmp_path_factory, tmpdir, tmpdir_factory, unused_tcp_port, unused_tcp_port_factory, unused_udp_port, unused_udp_port_factory
>       use 'pytest --fixtures [testpath]' for help on them.

/app/tests/test_stripe_integration.py:282
__________ ERROR at setup of test_webhook_checkout_session_completed ___________
file /app/tests/test_stripe_integration.py, line 299
  @patch('app.services.stripe_service.stripe.Webhook.construct_event')
  def test_webhook_checkout_session_completed(mock_construct_event, client, db_session, test_transaction):
E       fixture 'client' not found
>       available fixtures: _session_event_loop, anyio_backend, anyio_backend_name, anyio_backend_options, auth_headers, cache, capfd, capfdbinary, caplog, capsys, capsysbinary, clean_db, db_session, doctest_namespace, event_loop, event_loop_policy, free_tcp_port, free_tcp_port_factory, free_udp_port, free_udp_port_factory, monkeypatch, pytestconfig, record_property, record_testsuite_property, record_xml_attribute, recwarn, test_org, test_transaction, test_user, tests/test_stripe_integration.py::<event_loop>, tmp_path, tmp_path_factory, tmpdir, tmpdir_factory, unused_tcp_port, unused_tcp_port_factory, unused_udp_port, unused_udp_port_factory
>       use 'pytest --fixtures [testpath]' for help on them.

/app/tests/test_stripe_integration.py:299
___________ ERROR at setup of test_webhook_payment_intent_succeeded ____________
file /app/tests/test_stripe_integration.py, line 350
  @patch('app.services.stripe_service.stripe.Webhook.construct_event')
  def test_webhook_payment_intent_succeeded(mock_construct_event, client, db_session, test_transaction):
E       fixture 'client' not found
>       available fixtures: _session_event_loop, anyio_backend, anyio_backend_name, anyio_backend_options, auth_headers, cache, capfd, capfdbinary, caplog, capsys, capsysbinary, clean_db, db_session, doctest_namespace, event_loop, event_loop_policy, free_tcp_port, free_tcp_port_factory, free_udp_port, free_udp_port_factory, monkeypatch, pytestconfig, record_property, record_testsuite_property, record_xml_attribute, recwarn, test_org, test_transaction, test_user, tests/test_stripe_integration.py::<event_loop>, tmp_path, tmp_path_factory, tmpdir, tmpdir_factory, unused_tcp_port, unused_tcp_port_factory, unused_udp_port, unused_udp_port_factory
>       use 'pytest --fixtures [testpath]' for help on them.

/app/tests/test_stripe_integration.py:350
_______________ ERROR at setup of test_webhook_missing_signature _______________
file /app/tests/test_stripe_integration.py, line 382
  def test_webhook_missing_signature(client):
E       fixture 'client' not found
>       available fixtures: _session_event_loop, anyio_backend, anyio_backend_name, anyio_backend_options, auth_headers, cache, capfd, capfdbinary, caplog, capsys, capsysbinary, clean_db, db_session, doctest_namespace, event_loop, event_loop_policy, free_tcp_port, free_tcp_port_factory, free_udp_port, free_udp_port_factory, monkeypatch, pytestconfig, record_property, record_testsuite_property, record_xml_attribute, recwarn, test_org, test_transaction, test_user, tests/test_stripe_integration.py::<event_loop>, tmp_path, tmp_path_factory, tmpdir, tmpdir_factory, unused_tcp_port, unused_tcp_port_factory, unused_udp_port, unused_udp_port_factory
>       use 'pytest --fixtures [testpath]' for help on them.

/app/tests/test_stripe_integration.py:382
=================================== FAILURES ===================================
_____________________________ test_get_retry_stats _____________________________
  + Exception Group Traceback (most recent call last):
  |   File "/usr/local/lib/python3.11/site-packages/starlette/_utils.py", line 79, in collapse_excgroups
  |     yield
  |   File "/usr/local/lib/python3.11/site-packages/starlette/middleware/base.py", line 183, in __call__
  |     async with anyio.create_task_group() as task_group:
  |   File "/usr/local/lib/python3.11/site-packages/anyio/_backends/_asyncio.py", line 781, in __aexit__
  |     raise BaseExceptionGroup(
  | ExceptionGroup: unhandled errors in a TaskGroup (1 sub-exception)
  +-+---------------- 1 ----------------
    | Traceback (most recent call last):
    |   File "/usr/local/lib/python3.11/site-packages/_pytest/runner.py", line 341, in from_call
    |     result: TResult | None = func()
    |                              ^^^^^^
    |   File "/usr/local/lib/python3.11/site-packages/_pytest/runner.py", line 242, in <lambda>
    |     lambda: runtest_hook(item=item, **kwds), when=when, reraise=reraise
    |             ^^^^^^^^^^^^^^^^^^^^^^^^^^^^^^^
    |   File "/usr/local/lib/python3.11/site-packages/pluggy/_hooks.py", line 512, in __call__
    |     return self._hookexec(self.name, self._hookimpls.copy(), kwargs, firstresult)
    |            ^^^^^^^^^^^^^^^^^^^^^^^^^^^^^^^^^^^^^^^^^^^^^^^^^^^^^^^^^^^^^^^^^^^^^^
    |   File "/usr/local/lib/python3.11/site-packages/pluggy/_manager.py", line 120, in _hookexec
    |     return self._inner_hookexec(hook_name, methods, kwargs, firstresult)
    |            ^^^^^^^^^^^^^^^^^^^^^^^^^^^^^^^^^^^^^^^^^^^^^^^^^^^^^^^^^^^^^
    |   File "/usr/local/lib/python3.11/site-packages/pluggy/_callers.py", line 167, in _multicall
    |     raise exception
    |   File "/usr/local/lib/python3.11/site-packages/pluggy/_callers.py", line 139, in _multicall
    |     teardown.throw(exception)
    |   File "/usr/local/lib/python3.11/site-packages/_pytest/threadexception.py", line 92, in pytest_runtest_call
    |     yield from thread_exception_runtest_hook()
    |   File "/usr/local/lib/python3.11/site-packages/_pytest/threadexception.py", line 68, in thread_exception_runtest_hook
    |     yield
    |   File "/usr/local/lib/python3.11/site-packages/pluggy/_callers.py", line 139, in _multicall
    |     teardown.throw(exception)
    |   File "/usr/local/lib/python3.11/site-packages/_pytest/unraisableexception.py", line 95, in pytest_runtest_call
    |     yield from unraisable_exception_runtest_hook()
    |   File "/usr/local/lib/python3.11/site-packages/_pytest/unraisableexception.py", line 70, in unraisable_exception_runtest_hook
    |     yield
    |   File "/usr/local/lib/python3.11/site-packages/pluggy/_callers.py", line 139, in _multicall
    |     teardown.throw(exception)
    |   File "/usr/local/lib/python3.11/site-packages/_pytest/logging.py", line 846, in pytest_runtest_call
    |     yield from self._runtest_for(item, "call")
    |   File "/usr/local/lib/python3.11/site-packages/_pytest/logging.py", line 829, in _runtest_for
    |     yield
    |   File "/usr/local/lib/python3.11/site-packages/pluggy/_callers.py", line 139, in _multicall
    |     teardown.throw(exception)
    |   File "/usr/local/lib/python3.11/site-packages/_pytest/capture.py", line 880, in pytest_runtest_call
    |     return (yield)
    |             ^^^^^
    |   File "/usr/local/lib/python3.11/site-packages/pluggy/_callers.py", line 139, in _multicall
    |     teardown.throw(exception)
    |   File "/usr/local/lib/python3.11/site-packages/_pytest/skipping.py", line 257, in pytest_runtest_call
    |     return (yield)
    |             ^^^^^
    |   File "/usr/local/lib/python3.11/site-packages/pluggy/_callers.py", line 121, in _multicall
    |     res = hook_impl.function(*args)
    |           ^^^^^^^^^^^^^^^^^^^^^^^^^
    |   File "/usr/local/lib/python3.11/site-packages/_pytest/runner.py", line 174, in pytest_runtest_call
    |     item.runtest()
    |   File "/usr/local/lib/python3.11/site-packages/_pytest/python.py", line 1627, in runtest
    |     self.ihook.pytest_pyfunc_call(pyfuncitem=self)
    |   File "/usr/local/lib/python3.11/site-packages/pluggy/_hooks.py", line 512, in __call__
    |     return self._hookexec(self.name, self._hookimpls.copy(), kwargs, firstresult)
    |            ^^^^^^^^^^^^^^^^^^^^^^^^^^^^^^^^^^^^^^^^^^^^^^^^^^^^^^^^^^^^^^^^^^^^^^
    |   File "/usr/local/lib/python3.11/site-packages/pluggy/_manager.py", line 120, in _hookexec
    |     return self._inner_hookexec(hook_name, methods, kwargs, firstresult)
    |            ^^^^^^^^^^^^^^^^^^^^^^^^^^^^^^^^^^^^^^^^^^^^^^^^^^^^^^^^^^^^^
    |   File "/usr/local/lib/python3.11/site-packages/pluggy/_callers.py", line 167, in _multicall
    |     raise exception
    |   File "/usr/local/lib/python3.11/site-packages/pluggy/_callers.py", line 139, in _multicall
    |     teardown.throw(exception)
    |   File "/usr/local/lib/python3.11/site-packages/pluggy/_callers.py", line 53, in run_old_style_hookwrapper
    |     return result.get_result()
    |            ^^^^^^^^^^^^^^^^^^^
    |   File "/usr/local/lib/python3.11/site-packages/pluggy/_result.py", line 103, in get_result
    |     raise exc.with_traceback(tb)
    |   File "/usr/local/lib/python3.11/site-packages/pluggy/_callers.py", line 38, in run_old_style_hookwrapper
    |     res = yield
    |           ^^^^^
    |   File "/usr/local/lib/python3.11/site-packages/pluggy/_callers.py", line 121, in _multicall
    |     res = hook_impl.function(*args)
    |           ^^^^^^^^^^^^^^^^^^^^^^^^^
    |   File "/usr/local/lib/python3.11/site-packages/_pytest/python.py", line 159, in pytest_pyfunc_call
    |     result = testfunction(**testargs)
    |              ^^^^^^^^^^^^^^^^^^^^^^^^
    |   File "/app/tests/test_retry.py", line 228, in test_get_retry_stats
    |     response = client.get("/v1/retry/stats", headers=auth_headers)
    |                ^^^^^^^^^^^^^^^^^^^^^^^^^^^^^^^^^^^^^^^^^^^^^^^^^^^
    |   File "/usr/local/lib/python3.11/site-packages/starlette/testclient.py", line 479, in get
    |     return super().get(
    |            ^^^^^^^^^^^^
    |   File "/usr/local/lib/python3.11/site-packages/httpx/_client.py", line 1053, in get
    |     return self.request(
    |            ^^^^^^^^^^^^^
    |   File "/usr/local/lib/python3.11/site-packages/starlette/testclient.py", line 451, in request
    |     return super().request(
    |            ^^^^^^^^^^^^^^^^
    |   File "/usr/local/lib/python3.11/site-packages/httpx/_client.py", line 825, in request
    |     return self.send(request, auth=auth, follow_redirects=follow_redirects)
    |            ^^^^^^^^^^^^^^^^^^^^^^^^^^^^^^^^^^^^^^^^^^^^^^^^^^^^^^^^^^^^^^^^
    |   File "/usr/local/lib/python3.11/site-packages/httpx/_client.py", line 914, in send
    |     response = self._send_handling_auth(
    |                ^^^^^^^^^^^^^^^^^^^^^^^^^
    |   File "/usr/local/lib/python3.11/site-packages/httpx/_client.py", line 942, in _send_handling_auth
    |     response = self._send_handling_redirects(
    |                ^^^^^^^^^^^^^^^^^^^^^^^^^^^^^^
    |   File "/usr/local/lib/python3.11/site-packages/httpx/_client.py", line 979, in _send_handling_redirects
    |     response = self._send_single_request(request)
    |                ^^^^^^^^^^^^^^^^^^^^^^^^^^^^^^^^^^
    |   File "/usr/local/lib/python3.11/site-packages/httpx/_client.py", line 1014, in _send_single_request
    |     response = transport.handle_request(request)
    |                ^^^^^^^^^^^^^^^^^^^^^^^^^^^^^^^^^
    |   File "/usr/local/lib/python3.11/site-packages/starlette/testclient.py", line 354, in handle_request
    |     raise exc
    |   File "/usr/local/lib/python3.11/site-packages/starlette/testclient.py", line 351, in handle_request
    |     portal.call(self.app, scope, receive, send)
    |   File "/usr/local/lib/python3.11/site-packages/anyio/from_thread.py", line 321, in call
    |     return cast(T_Retval, self.start_task_soon(func, *args).result())
    |                           ^^^^^^^^^^^^^^^^^^^^^^^^^^^^^^^^^^^^^^^^^^
    |   File "/usr/local/lib/python3.11/concurrent/futures/_base.py", line 456, in result
    |     return self.__get_result()
    |            ^^^^^^^^^^^^^^^^^^^
    |   File "/usr/local/lib/python3.11/concurrent/futures/_base.py", line 401, in __get_result
    |     raise self._exception
    |   File "/usr/local/lib/python3.11/site-packages/anyio/from_thread.py", line 252, in _call_func
    |     retval = await retval_or_awaitable
    |              ^^^^^^^^^^^^^^^^^^^^^^^^^
    |   File "/usr/local/lib/python3.11/site-packages/fastapi/applications.py", line 1133, in __call__
    |     await super().__call__(scope, receive, send)
    |   File "/usr/local/lib/python3.11/site-packages/starlette/applications.py", line 113, in __call__
    |     await self.middleware_stack(scope, receive, send)
    |   File "/usr/local/lib/python3.11/site-packages/starlette/middleware/errors.py", line 186, in __call__
    |     raise exc
    |   File "/usr/local/lib/python3.11/site-packages/starlette/middleware/errors.py", line 164, in __call__
    |     await self.app(scope, receive, _send)
    |   File "/usr/local/lib/python3.11/site-packages/starlette/middleware/cors.py", line 85, in __call__
    |     await self.app(scope, receive, send)
    |   File "/usr/local/lib/python3.11/site-packages/starlette/middleware/base.py", line 182, in __call__
    |     with recv_stream, send_stream, collapse_excgroups():
    |   File "/usr/local/lib/python3.11/contextlib.py", line 158, in __exit__
    |     self.gen.throw(typ, value, traceback)
    |   File "/usr/local/lib/python3.11/site-packages/starlette/_utils.py", line 85, in collapse_excgroups
    |     raise exc
    |   File "/usr/local/lib/python3.11/site-packages/starlette/middleware/base.py", line 184, in __call__
    |     response = await self.dispatch_func(request, call_next)
    |                ^^^^^^^^^^^^^^^^^^^^^^^^^^^^^^^^^^^^^^^^^^^^
    |   File "/app/app/middleware.py", line 44, in request_id_middleware
    |     response = await call_next(request)
    |                ^^^^^^^^^^^^^^^^^^^^^^^^
    |   File "/usr/local/lib/python3.11/site-packages/starlette/middleware/base.py", line 159, in call_next
    |     raise app_exc
    |   File "/usr/local/lib/python3.11/site-packages/starlette/middleware/base.py", line 144, in coro
    |     await self.app(scope, receive_or_disconnect, send_no_error)
    |   File "/usr/local/lib/python3.11/site-packages/starlette/middleware/exceptions.py", line 63, in __call__
    |     await wrap_app_handling_exceptions(self.app, conn)(scope, receive, send)
    |   File "/usr/local/lib/python3.11/site-packages/starlette/_exception_handler.py", line 53, in wrapped_app
    |     raise exc
    |   File "/usr/local/lib/python3.11/site-packages/starlette/_exception_handler.py", line 42, in wrapped_app
    |     await app(scope, receive, sender)
    |   File "/usr/local/lib/python3.11/site-packages/fastapi/middleware/asyncexitstack.py", line 18, in __call__
    |     await self.app(scope, receive, send)
    |   File "/usr/local/lib/python3.11/site-packages/starlette/routing.py", line 716, in __call__
    |     await self.middleware_stack(scope, receive, send)
    |   File "/usr/local/lib/python3.11/site-packages/starlette/routing.py", line 736, in app
    |     await route.handle(scope, receive, send)
    |   File "/usr/local/lib/python3.11/site-packages/starlette/routing.py", line 290, in handle
    |     await self.app(scope, receive, send)
    |   File "/usr/local/lib/python3.11/site-packages/fastapi/routing.py", line 123, in app
    |     await wrap_app_handling_exceptions(app, request)(scope, receive, send)
    |   File "/usr/local/lib/python3.11/site-packages/starlette/_exception_handler.py", line 53, in wrapped_app
    |     raise exc
    |   File "/usr/local/lib/python3.11/site-packages/starlette/_exception_handler.py", line 42, in wrapped_app
    |     await app(scope, receive, sender)
    |   File "/usr/local/lib/python3.11/site-packages/fastapi/routing.py", line 109, in app
    |     response = await f(request)
    |                ^^^^^^^^^^^^^^^^
    |   File "/usr/local/lib/python3.11/site-packages/fastapi/routing.py", line 387, in app
    |     raw_response = await run_endpoint_function(
    |                    ^^^^^^^^^^^^^^^^^^^^^^^^^^^^
    |   File "/usr/local/lib/python3.11/site-packages/fastapi/routing.py", line 290, in run_endpoint_function
    |     return await run_in_threadpool(dependant.call, **values)
    |            ^^^^^^^^^^^^^^^^^^^^^^^^^^^^^^^^^^^^^^^^^^^^^^^^^
    |   File "/usr/local/lib/python3.11/site-packages/starlette/concurrency.py", line 38, in run_in_threadpool
    |     return await anyio.to_thread.run_sync(func)
    |            ^^^^^^^^^^^^^^^^^^^^^^^^^^^^^^^^^^^^
    |   File "/usr/local/lib/python3.11/site-packages/anyio/to_thread.py", line 56, in run_sync
    |     return await get_async_backend().run_sync_in_worker_thread(
    |            ^^^^^^^^^^^^^^^^^^^^^^^^^^^^^^^^^^^^^^^^^^^^^^^^^^^^
    |   File "/usr/local/lib/python3.11/site-packages/anyio/_backends/_asyncio.py", line 2485, in run_sync_in_worker_thread
    |     return await future
    |            ^^^^^^^^^^^^
    |   File "/usr/local/lib/python3.11/site-packages/anyio/_backends/_asyncio.py", line 976, in run
    |     result = context.run(func, *args)
    |              ^^^^^^^^^^^^^^^^^^^^^^^^
    |   File "/app/app/routers/retry_policies.py", line 176, in get_retry_stats
    |     RecoveryAttempt.transaction
    | AttributeError: type object 'RecoveryAttempt' has no attribute 'transaction'
    +------------------------------------

During handling of the above exception, another exception occurred:
tests/test_retry.py:228: in test_get_retry_stats
    response = client.get("/v1/retry/stats", headers=auth_headers)
/usr/local/lib/python3.11/site-packages/starlette/testclient.py:479: in get
    return super().get(
/usr/local/lib/python3.11/site-packages/httpx/_client.py:1053: in get
    return self.request(
/usr/local/lib/python3.11/site-packages/starlette/testclient.py:451: in request
    return super().request(
/usr/local/lib/python3.11/site-packages/httpx/_client.py:825: in request
    return self.send(request, auth=auth, follow_redirects=follow_redirects)
/usr/local/lib/python3.11/site-packages/httpx/_client.py:914: in send
    response = self._send_handling_auth(
/usr/local/lib/python3.11/site-packages/httpx/_client.py:942: in _send_handling_auth
    response = self._send_handling_redirects(
/usr/local/lib/python3.11/site-packages/httpx/_client.py:979: in _send_handling_redirects
    response = self._send_single_request(request)
/usr/local/lib/python3.11/site-packages/httpx/_client.py:1014: in _send_single_request
    response = transport.handle_request(request)
/usr/local/lib/python3.11/site-packages/starlette/testclient.py:354: in handle_request
    raise exc
/usr/local/lib/python3.11/site-packages/starlette/testclient.py:351: in handle_request
    portal.call(self.app, scope, receive, send)
/usr/local/lib/python3.11/site-packages/anyio/from_thread.py:321: in call
    return cast(T_Retval, self.start_task_soon(func, *args).result())
/usr/local/lib/python3.11/concurrent/futures/_base.py:456: in result
    return self.__get_result()
/usr/local/lib/python3.11/concurrent/futures/_base.py:401: in __get_result
    raise self._exception
/usr/local/lib/python3.11/site-packages/anyio/from_thread.py:252: in _call_func
    retval = await retval_or_awaitable
/usr/local/lib/python3.11/site-packages/fastapi/applications.py:1133: in __call__
    await super().__call__(scope, receive, send)
/usr/local/lib/python3.11/site-packages/starlette/applications.py:113: in __call__
    await self.middleware_stack(scope, receive, send)
/usr/local/lib/python3.11/site-packages/starlette/middleware/errors.py:186: in __call__
    raise exc
/usr/local/lib/python3.11/site-packages/starlette/middleware/errors.py:164: in __call__
    await self.app(scope, receive, _send)
/usr/local/lib/python3.11/site-packages/starlette/middleware/cors.py:85: in __call__
    await self.app(scope, receive, send)
/usr/local/lib/python3.11/site-packages/starlette/middleware/base.py:182: in __call__
    with recv_stream, send_stream, collapse_excgroups():
/usr/local/lib/python3.11/contextlib.py:158: in __exit__
    self.gen.throw(typ, value, traceback)
/usr/local/lib/python3.11/site-packages/starlette/_utils.py:85: in collapse_excgroups
    raise exc
/usr/local/lib/python3.11/site-packages/starlette/middleware/base.py:184: in __call__
    response = await self.dispatch_func(request, call_next)
app/middleware.py:44: in request_id_middleware
    response = await call_next(request)
/usr/local/lib/python3.11/site-packages/starlette/middleware/base.py:159: in call_next
    raise app_exc
/usr/local/lib/python3.11/site-packages/starlette/middleware/base.py:144: in coro
    await self.app(scope, receive_or_disconnect, send_no_error)
/usr/local/lib/python3.11/site-packages/starlette/middleware/exceptions.py:63: in __call__
    await wrap_app_handling_exceptions(self.app, conn)(scope, receive, send)
/usr/local/lib/python3.11/site-packages/starlette/_exception_handler.py:53: in wrapped_app
    raise exc
/usr/local/lib/python3.11/site-packages/starlette/_exception_handler.py:42: in wrapped_app
    await app(scope, receive, sender)
/usr/local/lib/python3.11/site-packages/fastapi/middleware/asyncexitstack.py:18: in __call__
    await self.app(scope, receive, send)
/usr/local/lib/python3.11/site-packages/starlette/routing.py:716: in __call__
    await self.middleware_stack(scope, receive, send)
/usr/local/lib/python3.11/site-packages/starlette/routing.py:736: in app
    await route.handle(scope, receive, send)
/usr/local/lib/python3.11/site-packages/starlette/routing.py:290: in handle
    await self.app(scope, receive, send)
/usr/local/lib/python3.11/site-packages/fastapi/routing.py:123: in app
    await wrap_app_handling_exceptions(app, request)(scope, receive, send)
/usr/local/lib/python3.11/site-packages/starlette/_exception_handler.py:53: in wrapped_app
    raise exc
/usr/local/lib/python3.11/site-packages/starlette/_exception_handler.py:42: in wrapped_app
    await app(scope, receive, sender)
/usr/local/lib/python3.11/site-packages/fastapi/routing.py:109: in app
    response = await f(request)
/usr/local/lib/python3.11/site-packages/fastapi/routing.py:387: in app
    raw_response = await run_endpoint_function(
/usr/local/lib/python3.11/site-packages/fastapi/routing.py:290: in run_endpoint_function
    return await run_in_threadpool(dependant.call, **values)
/usr/local/lib/python3.11/site-packages/starlette/concurrency.py:38: in run_in_threadpool
    return await anyio.to_thread.run_sync(func)
/usr/local/lib/python3.11/site-packages/anyio/to_thread.py:56: in run_sync
    return await get_async_backend().run_sync_in_worker_thread(
/usr/local/lib/python3.11/site-packages/anyio/_backends/_asyncio.py:2485: in run_sync_in_worker_thread
    return await future
/usr/local/lib/python3.11/site-packages/anyio/_backends/_asyncio.py:976: in run
    result = context.run(func, *args)
app/routers/retry_policies.py:176: in get_retry_stats
    RecoveryAttempt.transaction
E   AttributeError: type object 'RecoveryAttempt' has no attribute 'transaction'
------------------------------ Captured log call -------------------------------
ERROR    app.middleware:middleware.py:61 {"duration_ms": 9.01, "event": "request_failed", "path": "/v1/retry/stats", "method": "GET", "request_id": "75698dbf-f809-465c-adbf-4031126149c2", "logger": "app.middleware", "level": "error", "app": "stealth-recovery", "environment": "development", "timestamp": "2025-10-18T20:12:04.665042Z", "exception": "Traceback (most recent call last):\n  File \"/usr/local/lib/python3.11/site-packages/starlette/middleware/base.py\", line 151, in call_next\n    message = await recv_stream.receive()\n              ^^^^^^^^^^^^^^^^^^^^^^^^^^^\n  File \"/usr/local/lib/python3.11/site-packages/anyio/streams/memory.py\", line 126, in receive\n    raise EndOfStream from None\nanyio.EndOfStream\n\nDuring handling of the above exception, another exception occurred:\n\nTraceback (most recent call last):\n  File \"/app/app/middleware.py\", line 44, in request_id_middleware\n    response = await call_next(request)\n               ^^^^^^^^^^^^^^^^^^^^^^^^\n  File \"/usr/local/lib/python3.11/site-packages/starlette/middleware/base.py\", line 159, in call_next\n    raise app_exc\n  File \"/usr/local/lib/python3.11/site-packages/starlette/middleware/base.py\", line 144, in coro\n    await self.app(scope, receive_or_disconnect, send_no_error)\n  File \"/usr/local/lib/python3.11/site-packages/starlette/middleware/exceptions.py\", line 63, in __call__\n    await wrap_app_handling_exceptions(self.app, conn)(scope, receive, send)\n  File \"/usr/local/lib/python3.11/site-packages/starlette/_exception_handler.py\", line 53, in wrapped_app\n    raise exc\n  File \"/usr/local/lib/python3.11/site-packages/starlette/_exception_handler.py\", line 42, in wrapped_app\n    await app(scope, receive, sender)\n  File \"/usr/local/lib/python3.11/site-packages/fastapi/middleware/asyncexitstack.py\", line 18, in __call__\n    await self.app(scope, receive, send)\n  File \"/usr/local/lib/python3.11/site-packages/starlette/routing.py\", line 716, in __call__\n    await self.middleware_stack(scope, receive, send)\n  File \"/usr/local/lib/python3.11/site-packages/starlette/routing.py\", line 736, in app\n    await route.handle(scope, receive, send)\n  File \"/usr/local/lib/python3.11/site-packages/starlette/routing.py\", line 290, in handle\n    await self.app(scope, receive, send)\n  File \"/usr/local/lib/python3.11/site-packages/fastapi/routing.py\", line 123, in app\n    await wrap_app_handling_exceptions(app, request)(scope, receive, send)\n  File \"/usr/local/lib/python3.11/site-packages/starlette/_exception_handler.py\", line 53, in wrapped_app\n    raise exc\n  File \"/usr/local/lib/python3.11/site-packages/starlette/_exception_handler.py\", line 42, in wrapped_app\n    await app(scope, receive, sender)\n  File \"/usr/local/lib/python3.11/site-packages/fastapi/routing.py\", line 109, in app\n    response = await f(request)\n               ^^^^^^^^^^^^^^^^\n  File \"/usr/local/lib/python3.11/site-packages/fastapi/routing.py\", line 387, in app\n    raw_response = await run_endpoint_function(\n                   ^^^^^^^^^^^^^^^^^^^^^^^^^^^^\n  File \"/usr/local/lib/python3.11/site-packages/fastapi/routing.py\", line 290, in run_endpoint_function\n    return await run_in_threadpool(dependant.call, **values)\n           ^^^^^^^^^^^^^^^^^^^^^^^^^^^^^^^^^^^^^^^^^^^^^^^^^\n  File \"/usr/local/lib/python3.11/site-packages/starlette/concurrency.py\", line 38, in run_in_threadpool\n    return await anyio.to_thread.run_sync(func)\n           ^^^^^^^^^^^^^^^^^^^^^^^^^^^^^^^^^^^^\n  File \"/usr/local/lib/python3.11/site-packages/anyio/to_thread.py\", line 56, in run_sync\n    return await get_async_backend().run_sync_in_worker_thread(\n           ^^^^^^^^^^^^^^^^^^^^^^^^^^^^^^^^^^^^^^^^^^^^^^^^^^^^\n  File \"/usr/local/lib/python3.11/site-packages/anyio/_backends/_asyncio.py\", line 2485, in run_sync_in_worker_thread\n    return await future\n           ^^^^^^^^^^^^\n  File \"/usr/local/lib/python3.11/site-packages/anyio/_backends/_asyncio.py\", line 976, in run\n    result = context.run(func, *args)\n             ^^^^^^^^^^^^^^^^^^^^^^^^\n  File \"/app/app/routers/retry_policies.py\", line 176, in get_retry_stats\n    RecoveryAttempt.transaction\nAttributeError: type object 'RecoveryAttempt' has no attribute 'transaction'"}
=============================== warnings summary ===============================
app/auth_schemas.py:25
  /app/app/auth_schemas.py:25: PydanticDeprecatedSince20: Support for class-based `config` is deprecated, use ConfigDict instead. Deprecated in Pydantic V2.0 to be removed in V3.0. See Pydantic V2 Migration Guide at https://errors.pydantic.dev/2.12/migration/
    class UserResponse(UserBase):

app/auth_schemas.py:36
  /app/app/auth_schemas.py:36: PydanticDeprecatedSince20: Support for class-based `config` is deprecated, use ConfigDict instead. Deprecated in Pydantic V2.0 to be removed in V3.0. See Pydantic V2 Migration Guide at https://errors.pydantic.dev/2.12/migration/
    class OrganizationResponse(BaseModel):

app/routers/retry_policies.py:29
  /app/app/routers/retry_policies.py:29: PydanticDeprecatedSince20: Support for class-based `config` is deprecated, use ConfigDict instead. Deprecated in Pydantic V2.0 to be removed in V3.0. See Pydantic V2 Migration Guide at https://errors.pydantic.dev/2.12/migration/
    class RetryPolicyResponse(BaseModel):

app/routers/retry_policies.py:55
  /app/app/routers/retry_policies.py:55: PydanticDeprecatedSince20: Support for class-based `config` is deprecated, use ConfigDict instead. Deprecated in Pydantic V2.0 to be removed in V3.0. See Pydantic V2 Migration Guide at https://errors.pydantic.dev/2.12/migration/
    class NotificationLogResponse(BaseModel):

app/main.py:108
  /app/app/main.py:108: DeprecationWarning: 
          on_event is deprecated, use lifespan event handlers instead.
  
          Read more about it in the
          [FastAPI docs for Lifespan Events](https://fastapi.tiangolo.com/advanced/events/).
          
    @app.on_event("startup")

../usr/local/lib/python3.11/site-packages/fastapi/applications.py:4574
  /usr/local/lib/python3.11/site-packages/fastapi/applications.py:4574: DeprecationWarning: 
          on_event is deprecated, use lifespan event handlers instead.
  
          Read more about it in the
          [FastAPI docs for Lifespan Events](https://fastapi.tiangolo.com/advanced/events/).
          
    return self.router.on_event(event_type)

tests/test_auth.py::test_register_new_user
tests/test_auth.py::test_register_duplicate_email
tests/test_auth.py::test_register_duplicate_org_slug
tests/test_auth.py::test_login_success
tests/test_auth.py::test_login_wrong_password
tests/test_auth.py::test_get_current_user
tests/test_auth.py::test_get_current_organization
  /app/app/routers/auth.py:102: PydanticDeprecatedSince20: The `from_orm` method is deprecated; set `model_config['from_attributes']=True` and use `model_validate` instead. Deprecated in Pydantic V2.0 to be removed in V3.0. See Pydantic V2 Migration Guide at https://errors.pydantic.dev/2.12/migration/
    user=UserResponse.from_orm(user),

tests/test_auth.py::test_register_new_user
tests/test_auth.py::test_register_duplicate_email
tests/test_auth.py::test_register_duplicate_org_slug
tests/test_auth.py::test_login_success
tests/test_auth.py::test_login_wrong_password
tests/test_auth.py::test_get_current_user
tests/test_auth.py::test_get_current_organization
  /app/app/routers/auth.py:103: PydanticDeprecatedSince20: The `from_orm` method is deprecated; set `model_config['from_attributes']=True` and use `model_validate` instead. Deprecated in Pydantic V2.0 to be removed in V3.0. See Pydantic V2 Migration Guide at https://errors.pydantic.dev/2.12/migration/
    organization=OrganizationResponse.from_orm(organization),

tests/test_auth.py::test_login_success
  /app/app/routers/auth.py:139: PydanticDeprecatedSince20: The `from_orm` method is deprecated; set `model_config['from_attributes']=True` and use `model_validate` instead. Deprecated in Pydantic V2.0 to be removed in V3.0. See Pydantic V2 Migration Guide at https://errors.pydantic.dev/2.12/migration/
    user=UserResponse.from_orm(user),

tests/test_auth.py::test_login_success
  /app/app/routers/auth.py:140: PydanticDeprecatedSince20: The `from_orm` method is deprecated; set `model_config['from_attributes']=True` and use `model_validate` instead. Deprecated in Pydantic V2.0 to be removed in V3.0. See Pydantic V2 Migration Guide at https://errors.pydantic.dev/2.12/migration/
    organization=OrganizationResponse.from_orm(user.organization),

tests/test_auth.py::test_get_current_user
  /app/app/routers/auth.py:149: PydanticDeprecatedSince20: The `from_orm` method is deprecated; set `model_config['from_attributes']=True` and use `model_validate` instead. Deprecated in Pydantic V2.0 to be removed in V3.0. See Pydantic V2 Migration Guide at https://errors.pydantic.dev/2.12/migration/
    return UserResponse.from_orm(current_user)

tests/test_auth.py::test_get_current_organization
  /app/app/routers/auth.py:157: PydanticDeprecatedSince20: The `from_orm` method is deprecated; set `model_config['from_attributes']=True` and use `model_validate` instead. Deprecated in Pydantic V2.0 to be removed in V3.0. See Pydantic V2 Migration Guide at https://errors.pydantic.dev/2.12/migration/
    return OrganizationResponse.from_orm(current_user.organization)

tests/test_retry.py::test_create_retry_policy
  /app/app/routers/retry_policies.py:95: PydanticDeprecatedSince20: The `dict` method is deprecated; use `model_dump` instead. Deprecated in Pydantic V2.0 to be removed in V3.0. See Pydantic V2 Migration Guide at https://errors.pydantic.dev/2.12/migration/
    **policy_data.dict()

-- Docs: https://docs.pytest.org/en/stable/how-to/capture-warnings.html
=========================== short test summary info ============================
FAILED tests/test_retry.py::test_get_retry_stats - AttributeError: type objec...
ERROR tests/test_stripe_integration.py::test_create_checkout_session_success
ERROR tests/test_stripe_integration.py::test_create_checkout_session_transaction_not_found
ERROR tests/test_stripe_integration.py::test_create_checkout_session_stripe_error
ERROR tests/test_stripe_integration.py::test_create_payment_link_success
ERROR tests/test_stripe_integration.py::test_get_session_status_success
ERROR tests/test_stripe_integration.py::test_get_session_status_not_found
ERROR tests/test_stripe_integration.py::test_webhook_checkout_session_completed
ERROR tests/test_stripe_integration.py::test_webhook_payment_intent_succeeded
ERROR tests/test_stripe_integration.py::test_webhook_missing_signature
!!!!!!!!!!!!!!!!!!!!!!!!!! stopping after 10 failures !!!!!!!!!!!!!!!!!!!!!!!!!!
============= 1 failed, 29 passed, 25 warnings, 9 errors in 17.32s =============

7.2 Extracting test summary...

Test Results:
  Passed: 29
  Failed: 1
  Errors: 9
  Total: 39
  Coverage: 74.4%
  ⚠️  Below target: 74.4% < 80%

✅ PHASE 7 COMPLETE
